Running Query: SELECT * FROM friendships1;
Something went wrong (1146, "Table 'friendship.friendships1' doesn't exist")
False
---------------------------------------------------------------------------------------------
    raise err.Error("Already closed")
pymysql.err.Error: Already closed
---------------------------------------------------------------------------------------------
Running Query: delete FROM friendships where id=1;
Something went wrong (1054, "Unknown column 'id' in 'where clause'")
False
--------------------------------------------------------------------------------------------------
Running Query: insert into users (first_name1,last_name) values('aa','bb');
Something went wrong (1054, "Unknown column 'first_name1' in 'field list'")
False
-----------------------------------------------------------------------------
Running Query: insert into users  values('aa','bb');
Something went wrong (1136, "Column count doesn't match value count at row 1")
False
--------------------------------------------------------------------------------------------
Running Query: update users set first_name ='a' where user_id = 3;
Something went wrong (1054, "Unknown column 'user_id' in 'where clause'")
False
-----------------------------------------------------------------------------------------------
Running Query: update users set id ='5' where id =1;
Something went wrong (1062, "Duplicate entry '5' for key 'PRIMARY'")
False
-----------------------------------------------------------------------------------------------
Running Query: update users set id =10 where first_name ='a';
None
-----------------------------------------------------------------------------------------------
Running Query: update users set id =10 where first_name ='aa';
Something went wrong (1062, "Duplicate entry '10' for key 'PRIMARY'")
False

